<?xml version="1.0" ?>
<sdf version='1.7'>

  <model name='FR5urdf'>
	<plugin
      filename="libControlMainFrameworkSystem.so"
      name="YF::MainFrameworkSystem">
    </plugin>

    <link name='base_link'>
      <inertial>
        <pose>-0.000319 0.042463 0.000297 0 -0 0</pose>
        <mass>0.599446</mass>
        <inertia>
          <ixx>0.00114206</ixx>
          <ixy>-7.1538e-06</ixy>
          <ixz>-5.6865e-06</ixz>
          <iyy>0.00167441</iyy>
          <iyz>6.63618e-06</iyz>
          <izz>0.00114168</izz>
        </inertia>
      </inertial>
      <collision name='base_link_collision'>
        <pose>0 0 0 0 -0 0</pose>
        <geometry>
          <mesh>
            <scale>1 1 1</scale>
            <uri>model://fr5_robotic_arm/meshes/base_link.STL</uri>
          </mesh>
        </geometry>
      </collision>
      <visual name='base_link_visual'>
        <pose>0 0 0 0 -0 0</pose>
        <geometry>
          <mesh>
            <scale>1 1 1</scale>
            <uri>model://fr5_robotic_arm/meshes/base_link.STL</uri>
          </mesh>
        </geometry>
        <material> 
	      <ambient>0.0 0.0 0.0 1</ambient>
          <diffuse>0.0 0.0 0.0 1</diffuse>
          <specular>0.8 0.8 0.8 1</specular> 
        </material>
      </visual>
    </link>
    <joint name='joint1' type='revolute'>
      <pose relative_to='base_link'>0 0 0.074 1.5708 0 0.051335</pose>
      <parent>base_link</parent>
      <child>link1</child>
      <axis>
        <xyz>0 1 0</xyz>
        <limit>
          <lower>-3.05433</lower>
          <upper>3.05433</upper>
          <effort>150</effort>
          <velocity>3.15</velocity>
        </limit>
        <dynamics>
          <spring_reference>0</spring_reference>
          <spring_stiffness>0</spring_stiffness>
        </dynamics>
      </axis>
	  <sensor name="joint1_ft" type="force_torque">
		<always_on>1</always_on>
		<update_rate>1000</update_rate>
		<visualize>true</visualize>
		<topic>joint1_ft</topic>
	  </sensor>
	 
    </joint>
    <link name='link1'>
      <pose relative_to='joint1'>0 0 0 0 -0 0</pose>
      <inertial>
        <pose>1e-06 0.072291 0.004092 0 -0 0</pose>
        <mass>1.62121</mass>
        <inertia>
          <ixx>0.00397289</ixx>
          <ixy>-8.72188e-09</ixy>
          <ixz>2.11892e-09</ixz>
          <iyy>0.00302865</iyy>
          <iyz>-4.76903e-05</iyz>
          <izz>0.00385313</izz>
        </inertia>
      </inertial>
      <collision name='link1_collision'>
        <pose>0 0 0 0 -0 0</pose>
        <geometry>
          <mesh>
            <scale>1 1 1</scale>
            <uri>model://fr5_robotic_arm/meshes/link1.STL</uri>
          </mesh>
        </geometry>
      </collision>
      <visual name='link1_visual'>
        <pose>0 0 0 0 -0 0</pose>
        <geometry>
          <mesh>
            <scale>1 1 1</scale>
            <uri>model://fr5_robotic_arm/meshes/link1.STL</uri>
          </mesh>
        </geometry>
        <material> 
	  			<ambient>0.0 0.0 0.0 1</ambient>
            	<diffuse>1.0 0.0 0.0 1</diffuse>
            	<specular>0.0 0.0 0.0 1</specular> 
        </material>
      </visual>
    </link>
    <joint name='joint2' type='revolute'>
      <pose relative_to='link1'>0 0.078 0.046619 0 0 -1.2908</pose>
      <parent>link1</parent>
      <child>link2</child>
      <axis>
        <xyz>0 0 1</xyz>
        <limit>
          <lower>-4.62512</lower>
          <upper>1.48353</upper>
          <effort>150</effort>
          <velocity>3.15</velocity>
        </limit>
        <dynamics>
          <spring_reference>0</spring_reference>
          <spring_stiffness>0</spring_stiffness>
        </dynamics>
      </axis>
    </joint>
    <link name='link2'>
      <pose relative_to='joint2'>0 0 0 0 -0 0</pose>
      <inertial>
        <pose>-0.2125 -0 0.087988 0 -0 0</pose>
        <mass>5.35537</mass>
        <inertia>
          <ixx>0.0105146</ixx>
          <ixy>1.02673e-07</ixy>
          <ixz>-3.20062e-09</ixz>
          <iyy>0.16884</iyy>
          <iyz>1.69634e-08</iyz>
          <izz>0.166559</izz>
        </inertia>
      </inertial>
      <collision name='link2_collision'>
        <pose>0 0 0 0 -0 0</pose>
        <geometry>
          <mesh>
            <scale>1 1 1</scale>
            <uri>model://fr5_robotic_arm/meshes/link2.STL</uri>
          </mesh>
        </geometry>
      </collision>
      <visual name='link2_visual'>
        <pose>0 0 0 0 -0 0</pose>
        <geometry>
          <mesh>
            <scale>1 1 1</scale>
            <uri>model://fr5_robotic_arm/meshes/link2.STL</uri>
          </mesh>
        </geometry>
        <material> 
		  <ambient>0.0 0.0 0.0 1</ambient>
		  <diffuse>1.0 0.5 0.0 1</diffuse>
		  <specular>0.0 0.0 0.0 1</specular> 
		</material>
      </visual> 
    </link>
    <joint name='joint3' type='revolute'>
      <pose relative_to='link2'>-0.425 0 0 0 0 -2.1133</pose>
      <parent>link2</parent>
      <child>link3</child>
      <axis>
        <xyz>0 0 1</xyz>
        <limit>
          <lower>-2.82743</lower>
          <upper>2.82743</upper>
          <effort>150</effort>
          <velocity>3.15</velocity>
        </limit>
        <dynamics>
          <spring_reference>0</spring_reference>
          <spring_stiffness>0</spring_stiffness>
        </dynamics>
      </axis>
    </joint>
    <link name='link3'>
      <pose relative_to='joint3'>0 0 0 0 -0 0</pose>
      <inertial>
        <pose>-0.187974 3e-06 -0.039977 0 -0 0</pose>
        <mass>2.84204</mass>
        <inertia>
          <ixx>0.00315129</ixx>
          <ixy>-1.61393e-07</ixy>
          <ixz>-0.00254266</ixz>
          <iyy>0.0628538</iyy>
          <iyz>1.15155e-09</iyz>
          <izz>0.0624206</izz>
        </inertia>
      </inertial>
      <collision name='link3_collision'>
        <pose>0 0 0 0 -0 0</pose>
        <geometry>
          <mesh>
            <scale>1 1 1</scale>
            <uri>model://fr5_robotic_arm/meshes/link3.STL</uri>
          </mesh>
        </geometry>
      </collision>
      <visual name='link3_visual'>
        <pose>0 0 0 0 -0 0</pose>
        <geometry>
          <mesh>
            <scale>1 1 1</scale>
            <uri>model://fr5_robotic_arm/meshes/link3.STL</uri>
          </mesh>
        </geometry>
        <material> 
	  			<ambient>0.0 0.0 0.0 1</ambient>
            	<diffuse>0.5 0.5 0.0 1</diffuse>
            	<specular>0.0 0.0 0.0 1</specular>  
        </material>
      </visual>
    </link>
    <joint name='joint4' type='revolute'>
      <pose relative_to='link3'>-0.39501 0 0.006276 0 0 -2.8791</pose>
      <parent>link3</parent>
      <child>link4</child>
      <axis>
        <xyz>0 0 1</xyz>
        <limit>
          <lower>-4.62512</lower>
          <upper>1.48353</upper>
          <effort>28</effort>
          <velocity>3.2</velocity>
        </limit>
        <dynamics>
          <spring_reference>0</spring_reference>
          <spring_stiffness>0</spring_stiffness>
        </dynamics>
      </axis>
    </joint>
    <link name='link4'>
      <pose relative_to='joint4'>0 0 0 0 -0 0</pose>
      <inertial>
        <pose>1e-06 -0.003738 0.047961 0 -0 0</pose>
        <mass>0.602649</mass>
        <inertia>
          <ixx>0.000799625</ixx>
          <ixy>1.28025e-09</ixy>
          <ixz>1.74167e-08</ixz>
          <iyy>0.00057224</iyy>
          <iyz>1.39849e-05</iyz>
          <izz>0.000736736</izz>
        </inertia>
      </inertial>
      <collision name='link4_collision'>
        <pose>0 0 0 0 -0 0</pose>
        <geometry>
          <mesh>
            <scale>1 1 1</scale>
            <uri>model://fr5_robotic_arm/meshes/link4.STL</uri>
          </mesh>
        </geometry>
      </collision>
      <visual name='link4_visual'>
        <pose>0 0 0 0 -0 0</pose>
        <geometry>
          <mesh>
            <scale>1 1 1</scale>
            <uri>model://fr5_robotic_arm/meshes/link4.STL</uri>
          </mesh>
        </geometry>
        <material> 
	  		<ambient>0.0 0.0 0.0 1</ambient>
            <diffuse>0.0 1.0 0.0 1</diffuse>
            <specular>0.0 0.0 0.0 1</specular> 
        </material>
      </visual>
    </link>
    <joint name='joint5' type='revolute'>
      <pose relative_to='link4'>0 -0.0532 0.052905 0 -0.24913 0</pose>
      <parent>link4</parent>
      <child>link5</child>
      <axis>
        <xyz>0 -1 0</xyz>
        <limit>
          <lower>-3.05433</lower>
          <upper>3.05433</upper>
          <effort>28</effort>
          <velocity>3.2</velocity>
        </limit>
        <dynamics>
          <spring_reference>0</spring_reference>
          <spring_stiffness>0</spring_stiffness>
        </dynamics>
      </axis>
    </joint>
    <link name='link5'>
      <pose relative_to='joint5'>0 0 0 0 -0 0</pose>
      <inertial>
        <pose>-1e-06 -0.045058 0.003845 0 -0 0</pose>
        <mass>0.585859</mass>
        <inertia>
          <ixx>0.000763045</ixx>
          <ixy>1.36488e-08</ixy>
          <ixz>5.65391e-10</ixz>
          <iyy>0.000724548</iyy>
          <iyz>1.05861e-05</iyz>
          <izz>0.000536034</izz>
        </inertia>
      </inertial>
      <collision name='link5_collision'>
        <pose>0 0 0 0 -0 0</pose>
        <geometry>
          <mesh>
            <scale>1 1 1</scale>
            <uri>model://fr5_robotic_arm/meshes/link5.STL</uri>
          </mesh>
        </geometry>
      </collision>
      <visual name='link5_visual'>
        <pose>0 0 0 0 -0 0</pose>
        <geometry>
          <mesh>
            <scale>1 1 1</scale>
            <uri>model://fr5_robotic_arm/meshes/link5.STL</uri>
          </mesh>
        </geometry>
        <material> 
	       <ambient>0.0 0.0 0.0 1</ambient>
           <diffuse>0.0 0.5 0.5 1</diffuse>
           <specular>0.0 0.0 0.0 1</specular> 
        </material>
      </visual>
    </link>
    <joint name='joint6' type='revolute'>
      <pose relative_to='link5'>0 -0.0488 0.054969 0 -0 0.49221</pose>
      <parent>link5</parent>
      <child>link6</child>
      <axis>
        <xyz>0 0 1</xyz>
        <limit>
          <lower>-3.05433</lower>
          <upper>3.05433</upper>
          <effort>28</effort>
          <velocity>3.2</velocity>
        </limit>
        <dynamics>
          <spring_reference>0</spring_reference>
          <spring_stiffness>0</spring_stiffness>
        </dynamics>
      </axis>
    </joint>
    <link name='link6'>
      <pose relative_to='joint6'>0 0 0 0 -0 0</pose>
      <inertial>
        <pose>7.8e-05 1.8e-05 0.021153 0 -0 0</pose>
        <mass>0.1946</mass>
        <inertia>
          <ixx>0.000102669</ixx>
          <ixy>-7.4583e-10</ixy>
          <ixz>-4.40372e-08</ixz>
          <iyy>0.000103106</iyy>
          <iyz>8.37294e-08</iyz>
          <izz>0.000154093</izz>
        </inertia>
      </inertial>
      <collision name='link6_collision'>
        <pose>0 0 0 0 -0 0</pose>
        <geometry>
          <mesh>
            <scale>1 1 1</scale>
            <uri>model://fr5_robotic_arm/meshes/link6.STL</uri>
          </mesh>
        </geometry>
      </collision>
      <visual name='link6_visual'>
        <pose>0 0 0 0 -0 0</pose>
        <geometry>
          <mesh>
            <scale>1 1 1</scale>
            <uri>model://fr5_robotic_arm/meshes/link6.STL</uri>
          </mesh>
        </geometry>
        <material> 
	      <ambient>0.0 0.0 0.0 1</ambient>
          <diffuse>0.0 0.0 0.1 1</diffuse>
          <specular>0.0 0.0 0.0 1</specular> 
        </material>
      </visual>
    </link>
	<!-->Fix the base link<-->
    <joint name="base_fixed" type="fixed">
	  <pose>0 0 0 0 0 0</pose>
      <parent>world</parent>
      <child>base_link</child>
    </joint>
  </model>

</sdf>
